<?xml version="1.0" ?>
<!-- =================================================================================== -->
<!-- |    This document was autogenerated by xacro from arm.urdf.xacro                 | -->
<!-- |    EDITING THIS FILE BY HAND IS NOT RECOMMENDED                                 | -->
<!-- =================================================================================== -->
<robot name="arm">
  <!-- Functions -->
  <!-- Joints -->
  <joint name="base_link_joint" type="prismatic">
    <origin rpy="0 0 0" xyz="0 -10 0"/>
    <parent link="base_link"/>
    <child link="a_link"/>
    <axis xyz="0 1 0"/>
    <!-- effort in N-m, velocity in rad/s -->
    <limit effort="30" lower="0" upper="20" velocity="1"/>
    <!-- damping in N-m-s/rad -->
    <dynamics damping="1.0"/>
  </joint>
  <joint name="a_joint" type="revolute">
    <origin rpy="0 0 0" xyz="19.923 20.023 54.02"/>
    <parent link="a_link"/>
    <child link="b_link"/>
    <axis xyz="0 1 0"/>
    <!-- effort in N-m, velocity in rad/s -->
    <limit effort="30" lower="-1.570796" upper="0" velocity="1"/>
    <!-- damping in N-m-s/rad -->
    <dynamics damping="1.0"/>
  </joint>
  <joint name="b_joint" type="revolute">
    <origin rpy="0 0 0" xyz="0 0 0"/>
    <parent link="b_link"/>
    <child link="c_link"/>
    <axis xyz="0 1 0"/>
    <!-- effort in N-m, velocity in rad/s -->
    <limit effort="30" lower="0" upper="3.141592" velocity="1"/>
    <!-- damping in N-m-s/rad -->
    <dynamics damping="1.0"/>
  </joint>
  <joint name="c_joint" type="revolute">
    <origin rpy="0 0 0" xyz="0 0 0"/>
    <parent link="c_link"/>
    <child link="d_link"/>
    <axis xyz="0 1 0"/>
    <!-- effort in N-m, velocity in rad/s -->
    <limit effort="30" lower="-3.141592" upper="3.141592" velocity="1"/>
    <!-- damping in N-m-s/rad -->
    <dynamics damping="1.0"/>
  </joint>
  <joint name="d_joint" type="revolute">
    <origin rpy="0 0 0" xyz="0 0 0"/>
    <parent link="d_link"/>
    <child link="e_link"/>
    <axis xyz="1 0 0"/>
    <!-- effort in N-m, velocity in rad/s -->
    <limit effort="30" lower="-3.141592" upper="3.141592" velocity="1"/>
    <!-- damping in N-m-s/rad -->
    <dynamics damping="1.0"/>
  </joint>
  <!-- Links -->
  <link name="base_link">
    <inertial>
      <mass value="3.0"/>
      <inertia ixx="102.5" ixy="0.0" ixz="0.0" iyy="24.5" iyz="0.0" izz="102.5"/>
    </inertial>
    <visual>
      <origin rpy="0 0 0" xyz="0 0 0"/>
      <geometry>
        <mesh filename="../meshes/rover_chassis.dae"/>
      </geometry>
      <material name="red">
        <color rgba="1 1 1 1"/>
      </material>
    </visual>
    <!--    <collision>-->
    <!--        <origin rpy="0 0 0" xyz="0 0 -9.5"/>-->
    <!--        <geometry>-->
    <!--            <mesh filename="package://robo_impls/urdf/rover.dae"/>-->
    <!--        </geometry>-->
    <!--    </collision> -->
  </link>
  <link name="a_link">
    <visual>
      <origin rpy="0 0 0" xyz="0 0 0"/>
      <geometry>
        <mesh filename="../meshes/arm_a.dae"/>
      </geometry>
      <material name="white">
        <color rgba="1 1 1 1"/>
      </material>
    </visual>
    <!--    <xacro:link-collision-cylinder radius="3.75" x1="0" y1="0" z1="-1.25" x2="0" y2="0" z2="-3.75"/>-->
    <!--    <xacro:link-collision-cylinder radius="1.75" x1="3.6467207" y1="3.6590503" z1="-0.75" x2="3.6467207"-->
    <!--                                   y2="3.6590503" z2="-2.6913988"/>-->
    <!--    <xacro:link-inertial z="-2.5" mass="0.5" ixx="2.3" iyy="2.3" izz="3.5"/>-->
  </link>
  <link name="b_link">
    <visual>
      <origin rpy="0 0 0" xyz="0 0 0"/>
      <geometry>
        <mesh filename="../meshes/arm_b_fix.dae"/>
      </geometry>
      <material name="orange">
        <color rgba="1 0.43 0 1"/>
      </material>
    </visual>
  </link>
  <link name="c_link">
    <visual>
      <origin rpy="0 0 0" xyz="0 0 0"/>
      <geometry>
        <mesh filename="../meshes/arm_c.dae"/>
      </geometry>
      <material name="yellow">
        <color rgba="1 1 0 1"/>
      </material>
    </visual>
  </link>
  <link name="d_link">
    <visual>
      <origin rpy="0 0 0" xyz="0 0 0"/>
      <geometry>
        <mesh filename="../meshes/arm_d.dae"/>
      </geometry>
      <material name="green">
        <color rgba="0.43 1 0 1"/>
      </material>
    </visual>
  </link>
  <link name="e_link">
    <visual>
      <origin rpy="0 0 0" xyz="0 0 0"/>
      <geometry>
        <mesh filename="../meshes/arm_e.dae"/>
      </geometry>
      <material name="blue">
        <color rgba="0 0 1 1"/>
      </material>
    </visual>
  </link>
</robot>
